<?xml version="1.0" ?>
<robot name="robot_arm" xmlns:xacro="http://www.ros.org/wiki/xacro">

<xacro:include filename="$(find robot_arm_description)/urdf/materials.xacro" />
<xacro:include filename="$(find robot_arm_description)/urdf/robot_arm.trans" />
<xacro:include filename="$(find robot_arm_description)/urdf/robot_arm.gazebo" />
<link name="world"/>
<link name="base_link">
  <inertial>
    <origin xyz="0.0024607011550564013 6.455733015215033e-10 0.0241964579063244" rpy="0 0 0"/>
    <mass value="0.13769209908471902"/>
    <!--<inertia ixx="0.000143" iyy="0.00016" izz="0.000229" ixy="-0.0" iyz="0.0" ixz="-6e-06"/>-->
	<inertia ixx="0" iyy="0" izz="0" ixy="0" iyz="0" ixz="0"/>
  </inertial>
  <visual>
    <origin xyz="0 0 0" rpy="0 0 0"/>
    <geometry>
      <mesh filename="package://robot_arm_description/meshes/base_link.stl" scale="0.001 0.001 0.001"/>
    </geometry>
  </visual>
  <collision>
    <origin xyz="0 0 0" rpy="0 0 0"/>
    <geometry>
      <mesh filename="package://robot_arm_description/meshes/base_link.stl" scale="0.001 0.001 0.001"/>
    </geometry>
  </collision>
</link>

<link name="waist_1">
  <inertial>
    <origin xyz="0.00318602649091635 0.013877747356906538 0.022689548276635066" rpy="0 0 0"/>
    <mass value="0.10800159155411357"/>
    <inertia ixx="7.4e-05" iyy="7.5e-05" izz="7.9e-05" ixy="-3e-06" iyz="-1.4e-05" ixz="-1.1e-05"/>
  </inertial>
  <visual>
    <origin xyz="0.0 -0.0 -0.0566" rpy="0 0 0"/>
    <geometry>
      <mesh filename="package://robot_arm_description/meshes/waist_1.stl" scale="0.001 0.001 0.001"/>
    </geometry>
  </visual>
  <collision>
    <origin xyz="0.0 -0.0 -0.0566" rpy="0 0 0"/>
    <geometry>
      <mesh filename="package://robot_arm_description/meshes/waist_1.stl" scale="0.001 0.001 0.001"/>
    </geometry>
  </collision>
</link>

<link name="arm1_1">
  <inertial>
    <origin xyz="0.04133751613396197 -0.007768202679351965 0.04152238032046518" rpy="0 0 0"/>
    <mass value="0.505446604180645"/>
    <inertia ixx="0.000463" iyy="0.000903" izz="0.000474" ixy="-1e-06" iyz="-1e-06" ixz="-0.000396"/>
  </inertial>
  <visual>
    <origin xyz="-0.013742 -0.0018 -0.097053" rpy="0 0 0"/>
    <geometry>
      <mesh filename="package://robot_arm_description/meshes/arm1_1.stl" scale="0.001 0.001 0.001"/>
    </geometry>
  </visual>
  <collision>
    <origin xyz="-0.013742 -0.0018 -0.097053" rpy="0 0 0"/>
    <geometry>
      <mesh filename="package://robot_arm_description/meshes/arm1_1.stl" scale="0.001 0.001 0.001"/>
    </geometry>
  </collision>
</link>

<link name="arm2_1">
  <inertial>
    <origin xyz="0.021875310017626437 0.01671146992191255 0.022052083955411417" rpy="0 0 0"/>
    <mass value="0.09671321602707647"/>
    <inertia ixx="6.6e-05" iyy="0.000103" izz="6.6e-05" ixy="8e-06" iyz="8e-06" ixz="-4.3e-05"/>
  </inertial>
  <visual>
    <origin xyz="-0.098595 -0.0018 -0.181906" rpy="0 0 0"/>
    <geometry>
      <mesh filename="package://robot_arm_description/meshes/arm2_1.stl" scale="0.001 0.001 0.001"/>
    </geometry>
  </visual>
  <collision>
    <origin xyz="-0.098595 -0.0018 -0.181906" rpy="0 0 0"/>
    <geometry>
      <mesh filename="package://robot_arm_description/meshes/arm2_1.stl" scale="0.001 0.001 0.001"/>
    </geometry>
  </collision>
</link>

<link name="arm3_1">
  <inertial>
    <origin xyz="0.010225315136705243 -0.0030655198679682485 0.017341165454192953" rpy="0 0 0"/>
    <mass value="0.025038543338458022"/>
    <inertia ixx="4e-06" iyy="6e-06" izz="4e-06" ixy="0.0" iyz="0.0" ixz="-1e-06"/>
  </inertial>
  <visual>
    <origin xyz="-0.166936 -0.0125 -0.243106" rpy="0 0 0"/>
    <geometry>
      <mesh filename="package://robot_arm_description/meshes/arm3_1.stl" scale="0.001 0.001 0.001"/>
    </geometry>
  </visual>
  <collision>
    <origin xyz="-0.166936 -0.0125 -0.243106" rpy="0 0 0"/>
    <geometry>
      <mesh filename="package://robot_arm_description/meshes/arm3_1.stl" scale="0.001 0.001 0.001"/>
    </geometry>
  </collision>
</link>

<link name="gripper_1">
  <inertial>
    <origin xyz="0.028485280332901375 0.004846546679879509 0.04072672947992795" rpy="0 0 0"/>
    <mass value="0.044561931204964"/>
    <inertia ixx="4.2e-05" iyy="4.7e-05" izz="3.1e-05" ixy="-1e-06" iyz="-1e-06" ixz="-2e-05"/>
  </inertial>
  <visual>
    <origin xyz="-0.1832 0.00285 -0.266441" rpy="0 0 0"/>
    <geometry>
      <mesh filename="package://robot_arm_description/meshes/gripper_1.stl" scale="0.001 0.001 0.001"/>
    </geometry>
  </visual>
  <collision>
    <origin xyz="-0.1832 0.00285 -0.266441" rpy="0 0 0"/>
    <geometry>
      <mesh filename="package://robot_arm_description/meshes/gripper_1.stl" scale="0.001 0.001 0.001"/>
    </geometry>
  </collision>
</link>

<link name="gripper_2">
  <inertial>
    <origin xyz="0.04 0.0 0.05" rpy="0 0 0"/>
    <mass value="0.0"/>
    <inertia ixx="0" iyy="0" izz="0" ixy="0" iyz="0" ixz="0"/>
  </inertial>
  <visual>
    <origin xyz="0.04 0.0 0.05" rpy="0 0 0"/>
    <geometry>
      <sphere radius="0.00"/>
    </geometry>
  </visual>
  <collision>
    <origin xyz="0.04 0.0 0.05" rpy="0 0 0"/>
    <geometry>
      <sphere radius="0.00"/>
    </geometry>
  </collision>
</link>

<joint name="base_joint" type="revolute">
  <origin xyz="0.0 0.0 0.0566" rpy="0 0 0"/>
  <parent link="base_link"/>
  <child link="waist_1"/>
  <axis xyz="-0.0 0.0 1.0"/>
  <limit upper="1.570796" lower="-1.570796" effort="1.075" velocity="6"/>
</joint>

<joint name="waist_joint" type="revolute">
  <origin xyz="0.013742 0.0018 0.040453" rpy="0 0 0"/>
  <parent link="waist_1"/>
  <child link="arm1_1"/>
  <axis xyz="0.0 -1.0 0.0"/>
  <limit upper="1.570796" lower="-1.27409" effort="1.075" velocity="6"/>
</joint>

<joint name="arm1_joint" type="revolute">
  <origin xyz="0.084853 0.0 0.084853" rpy="0 0 0"/>
  <parent link="arm1_1"/>
  <child link="arm2_1"/>
  <axis xyz="-0.0 1.0 -0.0"/>
  <limit upper="1.570796" lower="-1.570796" effort="1.075" velocity="6"/>
</joint>

<joint name="arm2_joint" type="revolute">
  <origin xyz="0.068341 0.0107 0.0612" rpy="0 0 0"/>
  <parent link="arm2_1"/>
  <child link="arm3_1"/>
  <axis xyz="0.707107 0.0 0.707107"/>
  <limit upper="1.570796" lower="-1.570796" effort="1.075" velocity="6"/>
</joint>

<joint name="arm3_joint" type="revolute">
  <origin xyz="0.016264 -0.01535 0.023335" rpy="0 0 0"/>
  <parent link="arm3_1"/>
  <child link="gripper_1"/>
  <axis xyz="-0.0 -1.0 0.0"/>
  <limit upper="1.570796" lower="-1.570796" effort="1.075" velocity="6"/>
</joint>

<joint name="fixed" type="fixed">
    <parent link="world"/>
    <child link="base_link"/>
    <origin xyz="0.0 0.0 0.0" rpy="0 0 0"/>
  </joint>

  <joint name="fixed2" type="fixed">
    <origin xyz="0.076264 0.005 0.093335" rpy="0 0 0"/>
    <parent link="gripper_1"/>
    <child link="gripper_2"/>
    <axis xyz="-0.0 -1.0 0.0"/>
  </joint>

</robot>
